NameError
Python 3.6.5: D:\ProgramFile\Anaconda\python.exe
Fri Nov 30 14:56:23 2018

A problem occurred in a Python script.  Here is the sequence of
function calls leading up to the error, in the order they occurred.

 D:\研一\项目\Auditing\mainWin.py in openQuestionCheckDialog(self=<mainWin.MyMainWindow object>)
  267 
  268                 if As == True:
  269                     A_suggestion_outcome = A_suggestion_check(self.A,self.xiaoqu,self.A_suggestion_check_result)
  270                     # print(type(A_necessity_outcome))
  271                     Asfilename = 'A_suggestion_result.xlsx'
A_suggestion_outcome undefined
A_suggestion_check = <function A_suggestion_check>
self = <mainWin.MyMainWindow object>
self.A =                        SID  COL       SCODE  ......  ...    NaN   NaN   NaN

[767 rows x 44 columns]
self.xiaoqu =                 VID    COUN COUNNAME   ...    NV...       2     NaN        1

[36 rows x 23 columns]
self.A_suggestion_check_result = Empty DataFrame
Columns: [year, sid, scode, name, code, 提示内容, townname, vname]
Index: []

 D:\研一\项目\Auditing\A_suggestion_check.py in A_suggestion_check(TableA=                       SID  COL       SCODE  ......  ...    NaN   NaN   NaN

[767 rows x 44 columns], xiaoqu=                VID    COUN COUNNAME   ...    NV...       2     NaN        1

[36 rows x 23 columns], result_table=Empty DataFrame
Columns: [year, sid, scode, name, code, 提示内容, townname, vname]
Index: [])
   51     # result = open(r'D:\研一\审核程序\src\审核结果输出\A_suggestion_check_result.txt', 'w')
   52     global A_suggestion_result
   53     A_suggestion_result.drop(A_suggestion_result.index, inplace=True)
   54     A_suggestion_result = result_table
   55 
A_suggestion_result undefined
inplace undefined
NameError: name 'A_suggestion_result' is not defined
    __cause__ = None
    __class__ = <class 'NameError'>
    __context__ = None
    __delattr__ = <method-wrapper '__delattr__' of NameError object>
    __dict__ = {}
    __dir__ = <built-in method __dir__ of NameError object>
    __doc__ = 'Name not found globally.'
    __eq__ = <method-wrapper '__eq__' of NameError object>
    __format__ = <built-in method __format__ of NameError object>
    __ge__ = <method-wrapper '__ge__' of NameError object>
    __getattribute__ = <method-wrapper '__getattribute__' of NameError object>
    __gt__ = <method-wrapper '__gt__' of NameError object>
    __hash__ = <method-wrapper '__hash__' of NameError object>
    __init__ = <method-wrapper '__init__' of NameError object>
    __init_subclass__ = <built-in method __init_subclass__ of type object>
    __le__ = <method-wrapper '__le__' of NameError object>
    __lt__ = <method-wrapper '__lt__' of NameError object>
    __ne__ = <method-wrapper '__ne__' of NameError object>
    __new__ = <built-in method __new__ of type object>
    __reduce__ = <built-in method __reduce__ of NameError object>
    __reduce_ex__ = <built-in method __reduce_ex__ of NameError object>
    __repr__ = <method-wrapper '__repr__' of NameError object>
    __setattr__ = <method-wrapper '__setattr__' of NameError object>
    __setstate__ = <built-in method __setstate__ of NameError object>
    __sizeof__ = <built-in method __sizeof__ of NameError object>
    __str__ = <method-wrapper '__str__' of NameError object>
    __subclasshook__ = <built-in method __subclasshook__ of type object>
    __suppress_context__ = False
    __traceback__ = <traceback object>
    args = ("name 'A_suggestion_result' is not defined",)
    with_traceback = <built-in method with_traceback of NameError object>

The above is a description of an error in a Python program.  Here is
the original traceback:

Traceback (most recent call last):
  File "D:\研一\项目\Auditing\mainWin.py", line 269, in openQuestionCheckDialog
    A_suggestion_outcome = A_suggestion_check(self.A,self.xiaoqu,self.A_suggestion_check_result)
  File "D:\研一\项目\Auditing\A_suggestion_check.py", line 53, in A_suggestion_check
    A_suggestion_result.drop(A_suggestion_result.index, inplace=True)
NameError: name 'A_suggestion_result' is not defined

